Workbook
Name Answers: References!$D$4:$D$7
Name ARBType: 'Business Enablement Svcs Tech'!#REF!
Name ARBType: Architecture!$C$4
Name ArchDomain: 'Business Enablement Svcs Tech'!#REF!
Name ArchDomain: Architecture!$C$7
Name Category: 'Arch Alignment to Standandards'!#REF!
Name Category: #REF!
Name DPIAStatus: 'Data Privacy'!#REF!
Name Exception_Expiry: 'Arch Alignment to Standandards'!#REF!
Name Exception_Expiry: #REF!
Name Exception_Granted: 'Arch Alignment to Standandards'!#REF!
Name Exception_Granted: #REF!
Name Gateways: References!#REF!
Name Score: 'Arch Alignment to Standandards'!$E$5:$E$1048576
Name Score: #REF!
Name Version: References!#REF!

Sheet Change Log
A1: Date | B1: Author | C1: Description
A2: 45590 | B2: Bobby Willoughby | C2: Added "Azure Entra ID" as an option in Line 18, Identity
A3: 45604 | B3: Bobby Willoughby | C3: Corrected "data valuation"" for Identity Question (Line 18) to accommodate for the addition of the Azure Entra ID
A4: 45604 | B4: Bobby Willoughby | C4: Added this Change Log
A5: 45819 | B5: Bobby Willoughby | C5: Formula changes to allow for easier REFERENCE changes

Sheet Pre-Post ARB Checklist
B1: This document lists the pre and post ARB requirements from GTS Architects and GTS Architecture Delivery Product Owner/ARB Facilitator.
B3: Pre GTS ARB:
B4: Create a directory to serve as a repository for architecture documents in the GTS Solution Design repository.
B5: Copy the official version of the proper design document and scorecard from the GTS ARB SharePoint site to the above directory.
B6: Complete the Architecture Alignment to Standards Scorecard.
B7: Complete the design document and send it out for Peer Review and signoffs from requestor.
B8: Open an ARB Request, ensuring all required fields are completed.
B9: Create a PowerPoint presentation for review/approve at Readiness Check. Any changes made in Readiness Check will also be documented before review at GTS ARB.
B10: Once the peer feedback is considered, create a request on ARB SharePoint, if not already done.
B11: Ensure the Scorecard meets minimum of 90% score.
B12: · Note the scorecard of any architecture exceptions due to not meeting a requirement.
B13: · Architecture exceptions should be logged. You do not need to wait for approval to do this.
... B29: If the work is being handed over to an operational team, send a handover email to the Operational teams and requestor. Include GTS PMO if project management resources needs are determined.
B31: If there are Risk Exceptions in the Technical Risk Assessment, are Risks Acceptances documented in the appropriate ServiceNow form? | M31: Exceptions to standards are logged as GTS Risk Acceptances
B32: If there are Risk Exceptions in the Technical Risk Assessment, are Risks Remediations documented in the appropriate ServiceNow form? | M32: Exceptions to standards are logged as GTS Risk Remediations.

Sheet Arch Alignment to Standandards
D1: Architecture Alignment to Standards: | E1: =SUM(E4:E32)/COUNT(E4:E32) -> #REF!
A2: Category | B2: Review Group | C2: Question | D2: Answer | E2: Architecture Standards & Policies Alignment Score | F2: Exception to Standards - Link to Risk Acceptance, Risk Remediation, or explanation | G2: Where to find more information to be able to answer this question or complete the activity for being able to answer the question
A3: Architecture | C3: What is the type of architecture review board approval requested? | E3: N/A | G3: See Slide 7 of GTS ARB Charter
A4: Architecture | C4: Architecture peer review completed | D4: No | E4: =IF(D4 = "Yes",1,IF(D4 = "N/A",1,0)) -> 0
A5: Architecture | C5: Will the solution be deployed to an approved environment (Physical DataCenter, AWS, Azure, SaaS, PaaS)? | D5: N/A | E5: =VLOOKUP(D5,References!#REF!,2,FALSE) -> #REF!
A6: Architecture | C6: What region is the solution hosted in? | D6: N/A | E6: =VLOOKUP(D6,References!#REF!,2,FALSE) -> #REF!
A7: Architecture | C7: If this is Project Solution - Design ARB, within the solution design document and ARB presentation, is the Impacted Technology Components table populated, including CMDB IDs for all technology components currently in production or with a 'New' indicator for components to be added to the CMDB? | E7: =IF(D7="Yes",1,IF(D7="Not Applicable For This Type of ARB",1,0)) -> 0
A8: Architecture | C8: Are observability, monitoring, and logging requirements defined and accounted for within the solution design and architecture? | E8: =IF(D8="Yes",1,IF(D8="N/A",1,0)) -> 0
A9: Architecture | C9: Are fault tolerance and resiliency requirements defined and accounted for within the solution design and architecture (high availability, failover, redundancy, scalability)? | E9: =IF(D9="Yes",1,IF(D9="N/A",1,0)) -> 0
A10: Architecture | C10: What is the Availability Objective for the solution? | D10: Availability requirement is not defined | E10: =VLOOKUP(D10,References!B:C,2,FALSE) -> 0 | G10: Availability Objectives
A11: Architecture | C11: Is the solution architecture aligned with disaster recovery requirements for the solution? | D11: N/A | E11: =VLOOKUP(D11,References!D:E,2,FALSE) -> 1
A12: Architecture | C12: Is the solution architecture aligned with backup/recovery requirements for the solution? | D12: N/A | E12: =VLOOKUP(D12,References!D:E,2,FALSE) -> 1
A13: Architecture | C13: Is the deployment pattern for the solution documented within the solution architecture? | D13: N/A | E13: =VLOOKUP(D13,References!D:E,2,FALSE) -> 1
A14: Architecture | C14: Is the solution aligned with GTS Enterprise Architecture Principles? | D14: N/A | E14: =VLOOKUP(D14,References!D:E,2,FALSE) -> 1 | G14: GTS Architecture Principles
A15: Architecture | C15: If the solution interfaces with an application or exchanges data with an application that is a non-Aegon entity, are the approved pattern(s) for third party integration documented within the solution architecture? | D15: N/A | E15: =VLOOKUP(D15,References!D:E,2,FALSE) -> 1 | G15: GTS Architecture Repository - https://aegonna.sharepoint.com/sites/GEA/SitePages/Architecture-Documents.aspx Global Architecture Repository - https://aegonna.sharepoint.com/sites/GTS-GlobalARB/SitePages/Global-Architecture-Repository.aspx
A16: Architecture | C16: If the solution interfaces with an internal application or exchanges data with an internal application, are the approved patterns for internal integration documented within the solution architecture? | D16: N/A | E16: =VLOOKUP(D16,References!D:E,2,FALSE) -> 1 | G16: GTS Architecture Repository - https://aegonna.sharepoint.com/sites/GEA/SitePages/Architecture-Documents.aspx Global Architecture Repository - https://aegonna.sharepoint.com/sites/GTS-GlobalARB/SitePages/Global-Architecture-Repository.aspx
A17: Architecture | B17: GEA Review Board, Pre-ARB??? | C17: Has the solution passed the BU Architecture Board review? | D17: N/A | E17: =VLOOKUP(D17,References!D:E,2,FALSE) -> 1
A18: Architecture | C18: If the solution is dependent on identity, what is the identity management / identity provider utilized by the solution? | D18: Other | E18: =VLOOKUP(D18,References!#REF!,2,FALSE) -> #REF!
A19: Architecture | C19: What Secrets Vault is used for secrets management? | D19: Other | E19: =VLOOKUP(D19,References!#REF!,2,FALSE) -> #REF!
A20: Gen AI | B20: GEA Review Board, Pre-ARB??? | C20: If the solution has a dependency on GEN AI has it been logged in the GEN AI Inventory? | D20: N/A | E20: =VLOOKUP(D20,References!D:E,2,FALSE) -> 1 | G20: Link to GenAi Inventory
A21: Gen AI | B21: GEA Review Board, Pre-ARB??? | C21: If the solution has a dependency on GEN AI has it be reviewed and approved by the GEN AI Working Group? | D21: N/A | E21: =VLOOKUP(D21,References!D:E,2,FALSE) -> 1 | G21: Link to GenAi Inventory Gen AI Approval Status is "Approved" for the use case
A22: Compliance & Risk | C22: Technology Solution Assessment (TSA) Status | D22: Assessment Required, Not Initiated | E22: =VLOOKUP(D22,References!S:T,2,FALSE) -> -1 | G22: Link to Technology Risk Assessment Sharepoint Site
A23: Data Privacy | C23: Data Privacy Impact Assessment (DPIA) status If this is a Solution Design and the solution leverages new data sources or new use cases for data | D23: Assessment Required, Not Initiated | E23: =VLOOKUP(D23,References!S:T,2,FALSE) -> -1 | G23: Refer to the ITCF Framework and ICTF P04.01.02 Information Security Classification Standard for guidance on data classification the controls for processing, storing and transmitting data. - ITCF Framework: https://aegonna.sharepoint.com/sites/GTS-ICC/Intranet/ITCF/Shared%20Documents/Aegon%20Global%20IT%20Control%20Framework.pdf
A24: Infrastructure | C24: Infrastructure Review/Approval Status | D24: Assessment Required, Not Initiated | E24: =VLOOKUP(D24,References!S:T,2,FALSE) -> -1 | G24: Stefan Simenon is the Infrastructure Representative
A25: Security | B25: CCAT | C25: If this is a Final ARB for Solution Design, does the solution introduce new critical or high vulnerabilities that are unresolved? | D25: Not Final ARB | E25: =VLOOKUP(D25,References!Y:Z,2,FALSE) -> 1
A26: Architecture | B26: GEA Review Board, Pre-ARB??? | C26: If this is a Final ARB for Solution Design, are component standards, architecture design patterns, and reference architectures utilized by the solution in the GTS or Global architecture repository? | D26: Not Final ARB | E26: =VLOOKUP(D26,References!W:X,2,FALSE) -> 1 | G26: GTS Architecture Repository - https://aegonna.sharepoint.com/sites/GEA/SitePages/Architecture-Documents.aspx Global Architecture Repository - https://aegonna.sharepoint.com/sites/GTS-GlobalARB/SitePages/Global-Architecture-Repository.aspx
A27: Architecture | C27: If this is a Final ARB for Solution Design, are 'New' Business Applications introduced by the solution registered in CMDB and is risk rating completed? | D27: Not Final ARB | E27: =VLOOKUP(D27,References!Y:Z,2,FALSE) -> 1 | G27: CMDB Link - Risk Rating must be completed prior to approving Final ARB. Completing the Application Risk rating is the responsibility of the Application Owner.
A28: Architecture | B28: CSAT | C28: If this is a Final ARB for Solution Design, does the solution use approved machine / container images? | D28: Not Final ARB | E28: =VLOOKUP(D28,References!W:X,2,FALSE) -> 1 | G28: Link to Approved Container/Images Documentation Needs to be Added Here
A29: Compliance & Risk | C29: If this is a Final ARB for Solution Design, is GTS First Line Risk & Controls ARB Readiness acknowledgement completed and attached to GTS ARB agenda request? | D29: Not Final ARB | E29: =VLOOKUP(D29,References!W:X,2,FALSE) -> 1 | G29: To initiate this request, contact gtsiccriskandcontrol@transamerica.com
A30: Data Privacy | B30: Data Governance | C30: If this is a Final ARB for Solution Design, is GTS Data Privacy Officer ARB readiness acknowledgement completed and attached to GTS ARB agenda request? | D30: Not Final ARB | E30: =VLOOKUP(D30,References!W:X,2,FALSE) -> 1 | G30: To initiate this request, contact Adam Kaminsky
A31: Quality Assurance | C31: If this is a Final ARB for Solution Design, does the technology lead responsible for the implementation agree that the solution has been tested and is ready for Project Solution - Final ARB? | D31: Not Final ARB | E31: =VLOOKUP(D31,References!W:X,2,FALSE) -> 1 | G31: This question is a part of the scorecard to confirm that there are no additional changes that would require a re-validation of the architecture prior to ARB sign off of the Final ARB.
A32: Security | C32: If this is a Final ARB for Solution Design, is the Security Review completed and ARB readiness sign off / approval attached to GTS ARB agenda request? | D32: Not Final ARB | E32: =VLOOKUP(D32,References!W:X,2,FALSE) -> 1 | G32: Representative is in ARB Readiness - Nick Russel, Chad Hunter, or Jeff Bain

Sheet Target Operating Model

Sheet Assessment Score
B2: =Architecture!A1 -> ARCHITECTURE DOMAIN | C2: =Architecture!D1 -> 1 | D2: =IF(C2<90%,"FAIL","PASS") -> PASS | F2: ='Gen AI'!A1 -> GEN AI DOMAIN | G2: ='Gen AI'!E1 -> 1 | H2: =IF(G2<90%,"FAIL","PASS") -> PASS
B3: BUSINESS ENABLEMENT TECH SERVICES | C3: ='Business Enablement Svcs Tech'!D1 -> 1 | D3: =IF(C3<90%,"FAIL","PASS") -> PASS | F3: =Security!A1 -> SECURITY DOMAIN | G3: =Security!D1 -> 0.81818182 | H3: =IF(G3<90%,"FAIL","PASS") -> FAIL
B4: ='Data Privacy'!A1 -> DATA DOMAIN | C4: ='Data Privacy'!E1 -> 0.33333333 | D4: =IF(C4<90%,"FAIL","PASS") -> FAIL | F4: =Risks!A1 -> RISKS DOMAIN | G4: =Risks!E1 -> 1 | H4: =IF(G4<90%,"FAIL","PASS") -> PASS
B6: =#REF! -> #REF! | C6: =#REF! -> #REF! | D6: =IF(C6<90%,"FAIL","Pass") -> #REF! | E6: Remove this domain?
B7: =Performance!A1 -> PERFORMANCE DOMAIN | C7: =Performance!E1 -> 1 | D7: =IF(C7<90%,"FAIL","Pass") -> Pass | E7: Remove this domain?
B8: =NFRs!A1 -> NON FUNCTIONAL REQUIREMENTS DOMAIN | C8: =NFRs!E1 -> 1 | D8: =IF(C8<90%,"FAIL","Pass") -> Pass | E8: Remove this domain?
B9: Combined Score (AVG) | C9: =AVERAGE(C2:C5,G2:G4) -> 0.85858586 | D9: =IF(COUNTIF(D2:D5,"FAIL")+ COUNTIF(H2:H5,"FAIL")>1,"FAIL",IF(C9<90%,"FAIL","PASS")) -> FAIL | F9: If more than 1 Domain Failure or Average Score is < 90, then FAIL

Sheet Architecture
A1: ARCHITECTURE DOMAIN | D1: =SUM(D3:D18)/COUNT(D3:D18) -> 1
A2: Category | B2: Question | C2: Answer | D2: Scoring | E2: Comments to Explain Answer (Complete this column if explanation is necessary) | F2: Instructions | G2: Links and Further Instructions or Reference Material
A3: Architecture | B3: What is the Enterprise Architecture Classification? | C3: Core | D3: =VLOOKUP(C3,References!P:Q,2,FALSE) -> 1 | G3: =HYPERLINK("https://aegonna.sharepoint.com/:p:/r/sites/GEA/_layouts/15/Doc.aspx?sourcedoc=%7B751DCB16-8E6D-4CC5-BD0A-17AC94837E7C%7D&file=2026%20Enterprise%20Technology%20ARB%20Charter%20&%20Architecture%20Processes%20Overview.pptx=&action=edit&mobileredirect=true","2026 Enterprise Technology ARB Charter & Architecture Processes Overview.pptx") -> 2026 Enterprise Technology ARB Charter & Architecture Processes Overview.pptx | H3: =CONCATENATE("=hyperlink(""",M3,""",""",I3,""")") -> =hyperlink("https://aegonna.sharepoint.com/:p:/r/sites/GEA/_layouts/15/Doc.aspx?sourcedoc=%7B751DCB16-8E6D-4CC5-BD0A-17AC94837E7C%7D&file=2026%20Enterprise%20Technology%20ARB%20Charter%20&%20Architecture%20Processes%20Overview.pptx=&action=edit&mobileredirect=true","2026 Enterprise Technology ARB Charter & Architecture Processes Overview.pptx") | I3: 2026 Enterprise Technology ARB Charter & Architecture Processes Overview.pptx | M3: https://aegonna.sharepoint.com/:p:/r/sites/GEA/_layouts/15/Doc.aspx?sourcedoc=%7B751DCB16-8E6D-4CC5-BD0A-17AC94837E7C%7D&file=2026%20Enterprise%20Technology%20ARB%20Charter%20&%20Architecture%20Processes%20Overview.pptx=&action=edit&mobileredirect=true
A4: Architecture | B4: What is the type of architecture review board requested? | C4: Solution Design | D4: =VLOOKUP(C4,References!N:O,2,FALSE) -> 1 | G4: =HYPERLINK("https://aegonna.sharepoint.com/:p:/r/sites/GEA/_layouts/15/Doc.aspx?sourcedoc=%7B751DCB16-8E6D-4CC5-BD0A-17AC94837E7C%7D&file=2026%20Enterprise%20Technology%20ARB%20Charter%20&%20Architecture%20Processes%20Overview.pptx=&action=edit&mobileredirect=true","2026 Enterprise Technology ARB Charter & Architecture Processes Overview.pptx") -> 2026 Enterprise Technology ARB Charter & Architecture Processes Overview.pptx | H4: =CONCATENATE("=hyperlink(""",M4,""",""",I4,""")") -> =hyperlink("https://aegonna.sharepoint.com/:p:/r/sites/GEA/_layouts/15/Doc.aspx?sourcedoc=%7B751DCB16-8E6D-4CC5-BD0A-17AC94837E7C%7D&file=2026%20Enterprise%20Technology%20ARB%20Charter%20&%20Architecture%20Processes%20Overview.pptx=&action=edit&mobileredirect=true","2026 Enterprise Technology ARB Charter & Architecture Processes Overview.pptx") | I4: 2026 Enterprise Technology ARB Charter & Architecture Processes Overview.pptx | M4: https://aegonna.sharepoint.com/:p:/r/sites/GEA/_layouts/15/Doc.aspx?sourcedoc=%7B751DCB16-8E6D-4CC5-BD0A-17AC94837E7C%7D&file=2026%20Enterprise%20Technology%20ARB%20Charter%20&%20Architecture%20Processes%20Overview.pptx=&action=edit&mobileredirect=true
A5: Architecture | B5: Are the peer reviews completed and all comments resolved? | C5: Yes | D5: =VLOOKUP(C5,References!D:E,2,FALSE) -> 1 | F5: [When completing the scorecard, Include Reviewer Name(s) here]
A6: Architecture | B6: Has the architect considered workload placement options, using an objective framework to understand the workload hosting options? | C6: N/A | D6: =VLOOKUP(C6,References!D:E,2,FALSE) -> 1 | G6: =HYPERLINK("https://aegonna.sharepoint.com/:w:/r/sites/GTS-GlobalARB/_layouts/15/Doc.aspx?sourcedoc=%7BDE694E79-B787-4BF8-B39D-C8B841FCA44E%7D&file=Global%20Workload%20Placement%20Guidance.docx&action=default&mobileredirect=true","Global Workload Placement Guidance (2025)") -> Global Workload Placement Guidance (2025) | H6: =CONCATENATE("=hyperlink(""",M6,""",""",I6,""")") -> =hyperlink("https://aegonna.sharepoint.com/:w:/r/sites/GTS-GlobalARB/_layouts/15/Doc.aspx?sourcedoc=%7BDE694E79-B787-4BF8-B39D-C8B841FCA44E%7D&file=Global%20Workload%20Placement%20Guidance.docx&action=default&mobileredirect=true","Global Workload Placement Guidance (2025)") | I6: Global Workload Placement Guidance (2025) | M6: https://aegonna.sharepoint.com/:w:/r/sites/GTS-GlobalARB/_layouts/15/Doc.aspx?sourcedoc=%7BDE694E79-B787-4BF8-B39D-C8B841FCA44E%7D&file=Global%20Workload%20Placement%20Guidance.docx&action=default&mobileredirect=true
A7: Architecture | B7: What Architecture Domain does this solution fall into? | C7: Compute/Data | D7: =VLOOKUP(C7,References!AK:AL,2,FALSE) -> 1 | I7: Need to create cloud region guidance in 2026
A8: Architecture | B8: Is the solution deployed in an Aegon approved data center and cloud region? | C8: AWS - US East (N. Virginia + Ohio) | D8: =VLOOKUP(C8,References!AM:AN,2,FALSE) -> 1 | I8: Need to create cloud region guidance in 2026
A9: Architecture | B9: Is the solution aligned with the minimum TA and Global SDLC Standard's? | C9: N/A | D9: =VLOOKUP(C9,References!D:E,2,FALSE) -> 1 | G9: =HYPERLINK("https://aegonna.sharepoint.com/:x:/r/sites/TA-ProjectMethodology/_layouts/15/Doc.aspx?sourcedoc=%7BB2A86D3C-C120-4C87-9F1D-1591EEE31E5F%7D&file=SDLC%202.0%20Checklist%20and%20RACI.xlsx&action=default&mobileredirect=true","TA SDLC Checklist (2025)") -> TA SDLC Checklist (2025) | H9: =CONCATENATE("=hyperlink(""",M9,""",""",I9,""")") -> =hyperlink("https://aegonna.sharepoint.com/:x:/r/sites/TA-ProjectMethodology/_layouts/15/Doc.aspx?sourcedoc=%7BB2A86D3C-C120-4C87-9F1D-1591EEE31E5F%7D&file=SDLC%202.0%20Checklist%20and%20RACI.xlsx&action=default&mobileredirect=true","TA SDLC Checklist (2025)") | I9: TA SDLC Checklist (2025) | J9: =HYPERLINK("https://aegon.sharepoint.com/sites/CC-PolicyHouseGroup-10099/Shared%20Documents/Software%20Development%20Lifecycle%20Standard.pdf","Global SDLC Standard (2026)") -> Global SDLC Standard (2026) | K9: =CONCATENATE("=hyperlink(""",M9,""",""",L9,""")") -> =hyperlink("https://aegonna.sharepoint.com/:x:/r/sites/TA-ProjectMethodology/_layouts/15/Doc.aspx?sourcedoc=%7BB2A86D3C-C120-4C87-9F1D-1591EEE31E5F%7D&file=SDLC%202.0%20Checklist%20and%20RACI.xlsx&action=default&mobileredirect=true","Global SDLC Standard (2026)") | L9: =HYPERLINK("https://aegonna.sharepoint.com/:x:/r/sites/TA-ProjectMethodology/_layouts/15/Doc.aspx?sourcedoc=%7BB2A86D3C-C120-4C87-9F1D-1591EEE31E5F%7D&file=SDLC%202.0%20Checklist%20and%20RACI.xlsx&action=default&mobileredirect=true","Global SDLC Standard (2026)") -> Global SDLC Standard (2026) | M9: https://aegonna.sharepoint.com/:x:/r/sites/TA-ProjectMethodology/_layouts/15/Doc.aspx?sourcedoc=%7BB2A86D3C-C120-4C87-9F1D-1591EEE31E5F%7D&file=SDLC%202.0%20Checklist%20and%20RACI.xlsx&action=default&mobileredirect=true | N9: https://aegon.sharepoint.com/sites/CC-PolicyHouseGroup-10099/Shared%20Documents/Software%20Development%20Lifecycle%20Standard.pdf
A10: Architecture | B10: Is the solution aligned with the Enterprise Architecture Principles? | C10: Yes | D10: =VLOOKUP(C10,References!H:I,2,FALSE) -> 1 | G10: =HYPERLINK("https://aegonna.sharepoint.com/sites/GTS-GlobalARB/SitePages/Aegon-Global-Architecture-Principles.aspx?csf=1&web=1&e=qScbqN","Enterprise Architecture Principles (2025)") -> Enterprise Architecture Principles (2025) | H10: =CONCATENATE("=hyperlink(""",M10,""",""",I10,""")") -> =hyperlink("https://aegonna.sharepoint.com/sites/GTS-GlobalARB/SitePages/Aegon-Global-Architecture-Principles.aspx?csf=1&web=1&e=qScbqN","Enterprise Architecture Principles (2025)") | I10: Enterprise Architecture Principles (2025) | M10: https://aegonna.sharepoint.com/sites/GTS-GlobalARB/SitePages/Aegon-Global-Architecture-Principles.aspx?csf=1&web=1&e=qScbqN
A11: Architecture | B11: Is the solution aligned with the Well Architected Framework(s)? | C11: Yes | D11: =VLOOKUP(C11,References!H:I,2,FALSE) -> 1 | G11: =HYPERLINK("https://learn.microsoft.com/en-us/azure/well-architected/","https://learn.microsoft.com/en-us/azure/well-architected/") -> https://learn.microsoft.com/en-us/azure/well-architected/ | H11: =CONCATENATE("=hyperlink(""",M11,""",""",I11,""")") -> =hyperlink("https://learn.microsoft.com/en-us/azure/well-architected/","https://learn.microsoft.com/en-us/azure/well-architected/") | I11: https://learn.microsoft.com/en-us/azure/well-architected/ | J11: =HYPERLINK("https://aws.amazon.com/architecture/well-architected/","https://aws.amazon.com/architecture/well-architected/") -> https://aws.amazon.com/architecture/well-architected/ | K11: =CONCATENATE("=hyperlink(""",N11,""",""",L11,""")") -> =hyperlink("https://aws.amazon.com/architecture/well-architected/","https://aws.amazon.com/architecture/well-architected/") | L11: https://aws.amazon.com/architecture/well-architected/ | M11: https://learn.microsoft.com/en-us/azure/well-architected/ | N11: https://aws.amazon.com/architecture/well-architected/
A12: Architecture | B12: Is the solution aligned with the Free and Open-Source Software Guidance? | C12: N/A | D12: =VLOOKUP(C12,References!D:E,2,FALSE) -> 1 | G12: =HYPERLINK("https://aegonna.sharepoint.com/:p:/r/sites/GTS-GlobalARB/_layouts/15/Doc.aspx?sourcedoc=%7BAE7A5AE2-DEE6-431B-B2DC-41F5F2E2B6B9%7D&file=Global%20Free%20&%20Open%20Source%20Software%20(FOSS)%20Guidance.pptx=&action=edit&mobileredirect=true","Global Free & Open Source Software (FOSS) Guidance (2025)") -> Global Free & Open Source Software (FOSS) Guidance (2025) | H12: =CONCATENATE("=hyperlink(""",M12,""",""",I12,""")") -> =hyperlink("https://aegonna.sharepoint.com/:p:/r/sites/GTS-GlobalARB/_layouts/15/Doc.aspx?sourcedoc=%7BAE7A5AE2-DEE6-431B-B2DC-41F5F2E2B6B9%7D&file=Global%20Free%20&%20Open%20Source%20Software%20(FOSS)%20Guidance.pptx=&action=edit&mobileredirect=true","Global Free & Open Source Software (FOSS) Guidance (2025)") | I12: Global Free & Open Source Software (FOSS) Guidance (2025) | M12: https://aegonna.sharepoint.com/:p:/r/sites/GTS-GlobalARB/_layouts/15/Doc.aspx?sourcedoc=%7BAE7A5AE2-DEE6-431B-B2DC-41F5F2E2B6B9%7D&file=Global%20Free%20&%20Open%20Source%20Software%20(FOSS)%20Guidance.pptx=&action=edit&mobileredirect=true
A13: Architecture | B13: Is the solution aligned with our Global Logging, Monitoring, Observability & Alerting Guidance? | C13: Yes | D13: =VLOOKUP(C13,References!D:E,2,FALSE) -> 1 | G13: =HYPERLINK("https://aegonna.sharepoint.com/:w:/r/sites/GTS-GlobalARB/Aegon%20Global%20Architecture%20Policies%20and%20Standards/Global%20Logging,%20Monitoring,%20Observability%20%26%20Alerting%20Guidance.docx?d=w7489c70f511f4ad3a0705b1da976f51f&csf=1&web=1&e=fnstw3","Global Logging, Monitoring, Observability & Alerting Guidance (2025)") -> Global Logging, Monitoring, Observability & Alerting Guidance (2025) | H13: =CONCATENATE("=hyperlink(""",M13,""",""",I13,""")") -> =hyperlink("https://aegonna.sharepoint.com/:w:/r/sites/GTS-GlobalARB/Aegon%20Global%20Architecture%20Policies%20and%20Standards/Global%20Logging,%20Monitoring,%20Observability%20%26%20Alerting%20Guidance.docx?d=w7489c70f511f4ad3a0705b1da976f51f&csf=1&web=1&e=fnstw3","Global Logging, Monitoring, Observability & Alerting Guidance (2025)") | I13: Global Logging, Monitoring, Observability & Alerting Guidance (2025) | M13: https://aegonna.sharepoint.com/:w:/r/sites/GTS-GlobalARB/Aegon%20Global%20Architecture%20Policies%20and%20Standards/Global%20Logging,%20Monitoring,%20Observability%20%26%20Alerting%20Guidance.docx?d=w7489c70f511f4ad3a0705b1da976f51f&csf=1&web=1&e=fnstw3
A14: Architecture | B14: If the solution is introducing a new Tier 0 (Core Infrastructure), Tier 1 (Mission Critical), Tier 2 (Business Critical) or Tier 3 (Important) solution, is the Architecture Resiliency Tier & Design Criteria Assessment completed and in the Architecture Design Folder? | C14: Assessment Not Required | D14: =VLOOKUP(C14,References!S:T,2,FALSE) -> 1 | F14: <-- Include the link to the assessement as evidence | G14: =HYPERLINK("https://aegonna.sharepoint.com/:x:/r/sites/GEA/Templates/In%20Review/Architecture%20Resiliency%20Tier%20%26%20Design%20Criteria%20Assessment.xlsx?d=wdd5b89f510324f1f8e413e7b59c78c29&csf=1&web=1&e=KsRIX9","Architecture Resiliency Tier & Design Criteria Assessment") -> Architecture Resiliency Tier & Design Criteria Assessment | H14: =CONCATENATE("=hyperlink(""",M14,""",""",I14,""")") -> =hyperlink("https://aegonna.sharepoint.com/:x:/r/sites/GEA/Templates/In%20Review/Architecture%20Resiliency%20Tier%20%26%20Design%20Criteria%20Assessment.xlsx?d=wdd5b89f510324f1f8e413e7b59c78c29&csf=1&web=1&e=KsRIX9","Architecture Resiliency Tier & Design Criteria Assessment") | I14: Architecture Resiliency Tier & Design Criteria Assessment | J14: =HYPERLINK("https://aegonna.sharepoint.com/:p:/r/sites/GTS-GlobalARB/Aegon%20Global%20Architecture%20Policies%20and%20Standards/Global%20Resiliency%20Tiers%20and%20Design%20Guidance.pptx?d=w0670e2b0a05a42e98a99d6b0ee3d5a1b&csf=1&web=1&e=Bsj0ee","Global Resiliency Tiers & Design Criteria") -> Global Resiliency Tiers & Design Criteria | K14: =CONCATENATE("=hyperlink(""",N14,""",""",L14,""")") -> =hyperlink("https://aegonna.sharepoint.com/:p:/r/sites/GTS-GlobalARB/Aegon%20Global%20Architecture%20Policies%20and%20Standards/Global%20Resiliency%20Tiers%20and%20Design%20Guidance.pptx?d=w0670e2b0a05a42e98a99d6b0ee3d5a1b&csf=1&web=1&e=Bsj0ee","Global Resiliency Tiers & Design Criteria") | L14: Global Resiliency Tiers & Design Criteria | M14: https://aegonna.sharepoint.com/:x:/r/sites/GEA/Templates/In%20Review/Architecture%20Resiliency%20Tier%20%26%20Design%20Criteria%20Assessment.xlsx?d=wdd5b89f510324f1f8e413e7b59c78c29&csf=1&web=1&e=KsRIX9 | N14: https://aegonna.sharepoint.com/:p:/r/sites/GTS-GlobalARB/Aegon%20Global%20Architecture%20Policies%20and%20Standards/Global%20Resiliency%20Tiers%20and%20Design%20Guidance.pptx?d=w0670e2b0a05a42e98a99d6b0ee3d5a1b&csf=1&web=1&e=Bsj0ee
A15: Architecture | B15: Are cloud resource tags in place for all cloud resources hosted in Aegon AWS, ACE or Azure infrastructure used by the solution? | C15: N/A | D15: =VLOOKUP(C15,References!H:I,2,FALSE) -> 1 | F15: Required for Final ARB if the solution leverages aegon / transamerica AWS, ACE, Azure infrastructure | G15: =HYPERLINK("https://aegonna.sharepoint.com/:w:/r/sites/GTS-GlobalARB/Aegon%20Global%20Architecture%20Policies%20and%20Standards/Global%20Resource%20Tagging%20Standard.docx?d=w2d1b853fcbfe4e6cbf13d55a50fdaeb2&csf=1&web=1&e=j7C6HU","Global Resource Tagging Standards (2025)") -> Global Resource Tagging Standards (2025) | H15: =CONCATENATE("=hyperlink(""",M15,""",""",I15,""")") -> =hyperlink("https://aegonna.sharepoint.com/:w:/r/sites/GTS-GlobalARB/Aegon%20Global%20Architecture%20Policies%20and%20Standards/Global%20Resource%20Tagging%20Standard.docx?d=w2d1b853fcbfe4e6cbf13d55a50fdaeb2&csf=1&web=1&e=j7C6HU","Global Resource Tagging Standards (2025)") | I15: Global Resource Tagging Standards (2025) | M15: https://aegonna.sharepoint.com/:w:/r/sites/GTS-GlobalARB/Aegon%20Global%20Architecture%20Policies%20and%20Standards/Global%20Resource%20Tagging%20Standard.docx?d=w2d1b853fcbfe4e6cbf13d55a50fdaeb2&csf=1&web=1&e=j7C6HU
A16: Architecture | B16: Are the business applications, sdlc components and their application services mapped to related entities in ServiceNow per the Enterprise Architecture Metamodel? | C16: N/A | D16: =VLOOKUP(C16,References!D:E,2,FALSE) -> 1 | G16: =HYPERLINK("https://aegonna.sharepoint.com/:w:/r/sites/GTS-GlobalARB/Aegon%20Global%20Architecture%20Policies%20and%20Standards/Global%20Enterprise%20Architecture%20Metamodel%20Guidance.docx?d=w9bfb1f296d0142d89c35e70f1ef9a6da&csf=1&web=1&e=W0CUsA","Global EA Metamodel Guidance (2025)") -> Global EA Metamodel Guidance (2025) | H16: =CONCATENATE("=hyperlink(""",M16,""",""",I16,""")") -> =hyperlink("https://aegonna.sharepoint.com/:w:/r/sites/GTS-GlobalARB/Aegon%20Global%20Architecture%20Policies%20and%20Standards/Global%20Enterprise%20Architecture%20Metamodel%20Guidance.docx?d=w9bfb1f296d0142d89c35e70f1ef9a6da&csf=1&web=1&e=W0CUsA","Global EA Metamodel Guidance (2025)") | I16: Global EA Metamodel Guidance (2025) | M16: https://aegonna.sharepoint.com/:w:/r/sites/GTS-GlobalARB/Aegon%20Global%20Architecture%20Policies%20and%20Standards/Global%20Enterprise%20Architecture%20Metamodel%20Guidance.docx?d=w9bfb1f296d0142d89c35e70f1ef9a6da&csf=1&web=1&e=W0CUsA
A17: Architecture | B17: Final ARB for Solution Design: Are all referenced component standards, architecture design patterns, and reference architectures published in the architecture repository? | C17: N/A | D17: =VLOOKUP(C17,References!H:I,2,FALSE) -> 1 | G17: =HYPERLINK("https://aegonna.sharepoint.com/sites/GEA/SitePages/Architecture-Documents.aspx","ET Architecture Repository") -> ET Architecture Repository | H17: =CONCATENATE("=hyperlink(""",M17,""",""",I17,""")") -> =hyperlink("https://aegonna.sharepoint.com/sites/GEA/SitePages/Architecture-Documents.aspx","ET Architecture Repository") | I17: ET Architecture Repository | K17: =CONCATENATE("=hyperlink(""",M17,""",""",L17,""")") -> =hyperlink("https://aegonna.sharepoint.com/sites/GEA/SitePages/Architecture-Documents.aspx","Global Architecture Repository") | L17: =HYPERLINK("https://aegonna.sharepoint.com/sites/GEA/SitePages/Architecture-Documents.aspx","Global Architecture Repository") -> Global Architecture Repository | M17: https://aegonna.sharepoint.com/sites/GEA/SitePages/Architecture-Documents.aspx | N17: https://aegonna.sharepoint.com/sites/GTS-GlobalARB/SitePages/Global-Architecture-Repository.aspx | O17: Daca Architecture Repository
A18: Architecture | B18: Are impacted business applications risk-rated in the CMDB? | C18: N/A | D18: =VLOOKUP(C18,References!H:I,2,FALSE) -> 1 | F18: risk rating informs the minimum security requirements by app risk rating | G18: =HYPERLINK("https://aegon.service-now.com/now/nav/ui/classic/params/target/cmdb_ci_business_app_list.do","CMDB") -> CMDB | H18: =CONCATENATE("=hyperlink(""",M18,""",""",I18,""")") -> =hyperlink("https://aegon.service-now.com/now/nav/ui/classic/params/target/cmdb_ci_business_app_list.do","CMDB") | I18: CMDB | K18: =CONCATENATE("=hyperlink(""",M18,""",""",L18,""")") -> =hyperlink("https://aegon.service-now.com/now/nav/ui/classic/params/target/cmdb_ci_business_app_list.do","Global Minimum Security Requirements by App Risk Rating (2025)") | L18: =HYPERLINK("https://aegon.service-now.com/now/nav/ui/classic/params/target/cmdb_ci_business_app_list.do","Global Minimum Security Requirements by App Risk Rating (2025)") -> Global Minimum Security Requirements by App Risk Rating (2025) | M18: https://aegon.service-now.com/now/nav/ui/classic/params/target/cmdb_ci_business_app_list.do | N18: https://aegonna.sharepoint.com/:p:/s/GEA/cQr7F2hx5WGuQ7YvZOjTlEATEgUAegZ3q5TiBVPlY7cEx_fJkw

Sheet Business Enablement Svcs Tech
A1: BUSINESS ENABLEMENT (DINSTINCT ONLY) | D1: =SUM(D3:D9)/COUNT(D3:D9) -> 1
A2: Category | B2: Question | C2: Answer | D2: Scoring | E2: Comments to Explain Answer (Complete this column if explanation is necessary) | F2: Instructions | G2: Links and Further Instructions or Reference Material
A3: BUSINESS ENABLEMENT | B3: Do the sdlc components within the solution use the OnePlatform File Service to move files from source to target across internal (including Aegon cloud) platforms internally with required security, audit and compliance controls? | C3: Yes | D3: =VLOOKUP(C3,References!D:E,2,FALSE) -> 1 | G3: OnePlatform File Service (2025) | H3: https://aegonna.sharepoint.com/:w:/r/sites/TechnologySharedPlatform/Public/One%20Platform%20Services/7.%20File%20Service/User%20Guide.docx?d=wf54f72207c4348daab25f4d502df0be9&csf=1&web=1&e=lJKh6e | I3: =HYPERLINK(H3,G3) -> OnePlatform File Service (2025) | J3: =CONCATENATE("=hyperlink(""",H3,""",""",G3,""")") -> =hyperlink("https://aegonna.sharepoint.com/:w:/r/sites/TechnologySharedPlatform/Public/One%20Platform%20Services/7.%20File%20Service/User%20Guide.docx?d=wf54f72207c4348daab25f4d502df0be9&csf=1&web=1&e=lJKh6e","OnePlatform File Service (2025)") | K3: =HYPERLINK("https://aegonna.sharepoint.com/:w:/r/sites/TechnologySharedPlatform/Public/One%20Platform%20Services/7.%20File%20Service/User%20Guide.docx?d=wf54f72207c4348daab25f4d502df0be9&csf=1&web=1&e=lJKh6e","OnePlatform File Service (2025)") -> OnePlatform File Service (2025)
A4: BUSINESS ENABLEMENT | B4: Do the sdlc components within the solution use the OnePlatform Audit Logging Service to provide a secure, immutable audit log for events that need to record “who did what, when, and from where”? | C4: Yes | D4: =VLOOKUP(C4,References!D:E,2,FALSE) -> 1 | G4: OnePlatform Audit Logging User Guide V4 (2024) | H4: https://aegonna.sharepoint.com/:w:/r/sites/TechnologySharedPlatform/Public/One%20Platform%20Services/1.%20Audit%20Service/Oneplatform%20Audit%20Logging%20User%20Guide%20V4.docx?d=wce3b218e963f4448820c3d46c76a1c2a&csf=1&web=1&e=fYLivM | I4: =HYPERLINK(H4,G4) -> OnePlatform Audit Logging User Guide V4 (2024) | J4: =CONCATENATE("=hyperlink(""",H4,""",""",G4,""")") -> =hyperlink("https://aegonna.sharepoint.com/:w:/r/sites/TechnologySharedPlatform/Public/One%20Platform%20Services/1.%20Audit%20Service/Oneplatform%20Audit%20Logging%20User%20Guide%20V4.docx?d=wce3b218e963f4448820c3d46c76a1c2a&csf=1&web=1&e=fYLivM","OnePlatform Audit Logging User Guide V4 (2024)") | K4: =HYPERLINK("https://aegonna.sharepoint.com/:w:/r/sites/TechnologySharedPlatform/Public/One%20Platform%20Services/1.%20Audit%20Service/Oneplatform%20Audit%20Logging%20User%20Guide%20V4.docx?d=wce3b218e963f4448820c3d46c76a1c2a&csf=1&web=1&e=fYLivM","OnePlatform Audit Logging User Guide V4 (2024)") -> OnePlatform Audit Logging User Guide V4 (2024)
A5: BUSINESS ENABLEMENT | B5: Do the sdlc components within the solution use the OnePlatform Non-Repudiation Service to ensure users, systems, and external parties cannot deny having performed an action, submitted a transaction, or initiated a request after it has occurred? | C5: Yes | D5: =VLOOKUP(C5,References!D:E,2,FALSE) -> 1 | G5: OnePlatform Non-Repudiation Logging User Guide V2 (2023) | H5: https://aegonna.sharepoint.com/:w:/r/sites/TechnologySharedPlatform/Public/One%20Platform%20Services/8.%20Non-Repudiation%20Service/Oneplatform%20Non-Repudiation%20Logging%20User%20Guide%20V2.docx?d=w14b65ff341894f4b991fa4484b3a3b67&csf=1&web=1&e=cYYEKX | I5: =HYPERLINK(H5,G5) -> OnePlatform Non-Repudiation Logging User Guide V2 (2023) | J5: =CONCATENATE("=hyperlink(""",H5,""",""",G5,""")") -> =hyperlink("https://aegonna.sharepoint.com/:w:/r/sites/TechnologySharedPlatform/Public/One%20Platform%20Services/8.%20Non-Repudiation%20Service/Oneplatform%20Non-Repudiation%20Logging%20User%20Guide%20V2.docx?d=w14b65ff341894f4b991fa4484b3a3b67&csf=1&web=1&e=cYYEKX","OnePlatform Non-Repudiation Logging User Guide V2 (2023)") | K5: =HYPERLINK("https://aegonna.sharepoint.com/:w:/r/sites/TechnologySharedPlatform/Public/One%20Platform%20Services/8.%20Non-Repudiation%20Service/Oneplatform%20Non-Repudiation%20Logging%20User%20Guide%20V2.docx?d=w14b65ff341894f4b991fa4484b3a3b67&csf=1&web=1&e=cYYEKX","OnePlatform Non-Repudiation Logging User Guide V2 (2023)") -> OnePlatform Non-Repudiation Logging User Guide V2 (2023)
A6: BUSINESS ENABLEMENT | B6: Do the sdlc components within the solution use the OnePlatform User Notification Service to send outbound communications—email, SMS, and robocalls - for user notifications? | C6: Yes | D6: =VLOOKUP(C6,References!D:E,2,FALSE) -> 1 | G6: OnePlatform User Notification Guide (2025) | H6: https://aegonna.sharepoint.com/:w:/r/sites/TechnologySharedPlatform/Public/One%20Platform%20Services/9.%20User%20Notification%20Service/User%20Notification%20Guide.docx?d=we557168aa9154789b15cd99896fa1cdd&csf=1&web=1&e=LZwike | I6: =HYPERLINK(H6,G6) -> OnePlatform User Notification Guide (2025) | J6: =CONCATENATE("=hyperlink(""",H6,""",""",G6,""")") -> =hyperlink("https://aegonna.sharepoint.com/:w:/r/sites/TechnologySharedPlatform/Public/One%20Platform%20Services/9.%20User%20Notification%20Service/User%20Notification%20Guide.docx?d=we557168aa9154789b15cd99896fa1cdd&csf=1&web=1&e=LZwike","OnePlatform User Notification Guide (2025)") | K6: =HYPERLINK("https://aegonna.sharepoint.com/:w:/r/sites/TechnologySharedPlatform/Public/One%20Platform%20Services/9.%20User%20Notification%20Service/User%20Notification%20Guide.docx?d=we557168aa9154789b15cd99896fa1cdd&csf=1&web=1&e=LZwike","OnePlatform User Notification Guide (2025)") -> OnePlatform User Notification Guide (2025)
A7: BUSINESS ENABLEMENT | B7: Do the applications / sdlc components within the solution use the OnePlatform Event Notification Service to send event‑driven communication across Transamerica systems? | C7: Yes | D7: =VLOOKUP(C7,References!D:E,2,FALSE) -> 1 | G7: OnePlatform Event Notification Service User Guide v4 (2025) | H7: https://aegonna.sharepoint.com/:w:/r/sites/TechnologySharedPlatform/Public/One%20Platform%20Services/6.%20Event%20Notification%20Service/Event%20Notification%20Service%20User%20Guide%20v4.docx?d=we313efda14c34f17a43b2511200ac518&csf=1&web=1&e=8bSIjO | I7: =HYPERLINK(H7,G7) -> OnePlatform Event Notification Service User Guide v4 (2025) | J7: =CONCATENATE("=hyperlink(""",H7,""",""",G7,""")") -> =hyperlink("https://aegonna.sharepoint.com/:w:/r/sites/TechnologySharedPlatform/Public/One%20Platform%20Services/6.%20Event%20Notification%20Service/Event%20Notification%20Service%20User%20Guide%20v4.docx?d=we313efda14c34f17a43b2511200ac518&csf=1&web=1&e=8bSIjO","OnePlatform Event Notification Service User Guide v4 (2025)") | K7: =HYPERLINK("https://aegonna.sharepoint.com/:w:/r/sites/TechnologySharedPlatform/Public/One%20Platform%20Services/6.%20Event%20Notification%20Service/Event%20Notification%20Service%20User%20Guide%20v4.docx?d=we313efda14c34f17a43b2511200ac518&csf=1&web=1&e=8bSIjO","OnePlatform Event Notification Service User Guide v4 (2025)") -> OnePlatform Event Notification Service User Guide v4 (2025)
A8: BUSINESS ENABLEMENT | B8: Do the applications / sdlc components within the solution use the OnePlatform User Authorization Service to assign, manage, and enforce user permissions, roles, entitlements, and resource access? | C8: Yes | D8: =VLOOKUP(C8,References!D:E,2,FALSE) -> 1 | G8: OnePlatform User Authorization Service (2024) | H8: https://aegonna.sharepoint.com/:w:/r/sites/TechnologySharedPlatform/Public/One%20Platform%20Services/2.%20Authorization%20Service/ONE_PLATFORM_USER_AUTHORIZATION_SERVICE_USER_GUIDE.docx?d=wa20e16d56d1e462ea7d7b59ba5d38d5e&csf=1&web=1&e=QuVaGP | I8: =HYPERLINK(H8,G8) -> OnePlatform User Authorization Service (2024) | J8: =CONCATENATE("=hyperlink(""",H8,""",""",G8,""")") -> =hyperlink("https://aegonna.sharepoint.com/:w:/r/sites/TechnologySharedPlatform/Public/One%20Platform%20Services/2.%20Authorization%20Service/ONE_PLATFORM_USER_AUTHORIZATION_SERVICE_USER_GUIDE.docx?d=wa20e16d56d1e462ea7d7b59ba5d38d5e&csf=1&web=1&e=QuVaGP","OnePlatform User Authorization Service (2024)") | K8: =HYPERLINK("https://aegonna.sharepoint.com/:w:/r/sites/TechnologySharedPlatform/Public/One%20Platform%20Services/2.%20Authorization%20Service/ONE_PLATFORM_USER_AUTHORIZATION_SERVICE_USER_GUIDE.docx?d=wa20e16d56d1e462ea7d7b59ba5d38d5e&csf=1&web=1&e=QuVaGP","OnePlatform User Authorization Service (2024)") -> OnePlatform User Authorization Service (2024)
A9: BUSINESS ENABLEMENT | B9: Does the solution architecture / implementation leverage the One Platform Data Encryption service to ensure data is encrypted at rest and in transit? | C9: Yes | D9: =VLOOKUP(C9,References!D:E,2,FALSE) -> 1 | G9: OnePlatform Data Encryption Service User Guide (2022) | H9: https://aegonna.sharepoint.com/:w:/r/sites/TechnologySharedPlatform/Public/One%20Platform%20Services/5.%20Data%20Encryption%20Service/Data%20Encryption%20Service%20User%20Guide%20v3.docx?d=wd1c5e8ea80454db995c9db5c47d69ba9&csf=1&web=1&e=9cXkVf | I9: =HYPERLINK(H9,G9) -> OnePlatform Data Encryption Service User Guide (2022) | J9: =CONCATENATE("=hyperlink(""",H9,""",""",G9,""")") -> =hyperlink("https://aegonna.sharepoint.com/:w:/r/sites/TechnologySharedPlatform/Public/One%20Platform%20Services/5.%20Data%20Encryption%20Service/Data%20Encryption%20Service%20User%20Guide%20v3.docx?d=wd1c5e8ea80454db995c9db5c47d69ba9&csf=1&web=1&e=9cXkVf","OnePlatform Data Encryption Service User Guide (2022)") | K9: =HYPERLINK("https://aegonna.sharepoint.com/:w:/r/sites/TechnologySharedPlatform/Public/One%20Platform%20Services/5.%20Data%20Encryption%20Service/Data%20Encryption%20Service%20User%20Guide%20v3.docx?d=wd1c5e8ea80454db995c9db5c47d69ba9&csf=1&web=1&e=9cXkVf","OnePlatform Data Encryption Service User Guide (2022)") -> OnePlatform Data Encryption Service User Guide (2022)

Sheet Data Privacy
A1: DATA DOMAIN | E1: =SUM(E3:E8)/COUNT(E3:E8) -> 0.33333333
A2: Category | B2: Review Group | C2: Question | D2: Answer | E2: Scoring | F2: Comments to Explain Answer (Complete this column if explanation is necessary) | G2: Instructions | H2: Links and Further Instructions
A3: Data Privacy | C3: What is the Data Confidentiality Classification for data utilized within the solution? | D3: Unknown | E3: =VLOOKUP(D3,References!AA:AB,2,FALSE) -> -1 | H3: =HYPERLINK("https://aegon.service-now.com/asp?id=kb_article_view&sys_kb_id=a386a88ffbbff618247ffcbfbeefdc27","ITCF - Protect - P04.01.02 Information Security Classification Schema - Appendix A (2021)") -> ITCF - Protect - P04.01.02 Information Security Classification Schema - Appendix A (2021) | J3: https://aegonna.sharepoint.com/sites/GTS-ICC/Intranet/ITCF/Shared%20Documents/Forms/AllItems.aspx?id=%2Fsites%2FGTS%2DICC%2FIntranet%2FITCF%2FShared%20Documents%2FEnablers%20%26%20Checklists&viewid=99189f90%2Df2b0%2D478b%2Da980%2Df93a529e9b18 | K3: =CONCATENATE("=hyperlink(""",J3,""",""",H3,""")") -> =hyperlink("https://aegonna.sharepoint.com/sites/GTS-ICC/Intranet/ITCF/Shared%20Documents/Forms/AllItems.aspx?id=%2Fsites%2FGTS%2DICC%2FIntranet%2FITCF%2FShared%20Documents%2FEnablers%20%26%20Checklists&viewid=99189f90%2Df2b0%2D478b%2Da980%2Df93a529e9b18","ITCF - Protect - P04.01.02 Information Security Classification Schema - Appendix A (2021)") | L3: =HYPERLINK("https://aegonna.sharepoint.com/sites/GTS-ICC/Intranet/ITCF/Shared%20Documents/Forms/AllItems.aspx?id=%2Fsites%2FGTS%2DICC%2FIntranet%2FITCF%2FShared%20Documents%2FEnablers%20%26%20Checklists&viewid=99189f90%2Df2b0%2D478b%2Da980%2Df93a529e9b18","ITCF - Protect - P04.01.02 Information Security Classification Schema - Appendix A (2021)") -> ITCF - Protect - P04.01.02 Information Security Classification Schema - Appendix A (2021)
A4: Data Privacy | C4: What is the Legal & Regulatory Classification for data utilized within the solution? | D4: Unknown | E4: =VLOOKUP(D4,References!AC:AD,2,FALSE) -> -1 | H4: =HYPERLINK("https://aegon.service-now.com/asp?id=kb_article_view&sys_kb_id=a386a88ffbbff618247ffcbfbeefdc27","ITCF - Protect - P04.01.02 Information Security Classification Schema - Appendix A (2021)") -> ITCF - Protect - P04.01.02 Information Security Classification Schema - Appendix A (2021) | J4: https://aegonna.sharepoint.com/sites/GTS-ICC/Intranet/ITCF/Shared%20Documents/Forms/AllItems.aspx?id=%2Fsites%2FGTS%2DICC%2FIntranet%2FITCF%2FShared%20Documents%2FEnablers%20%26%20Checklists&viewid=99189f90%2Df2b0%2D478b%2Da980%2Df93a529e9b18 | K4: =CONCATENATE("=hyperlink(""",J4,""",""",H4,""")") -> =hyperlink("https://aegonna.sharepoint.com/sites/GTS-ICC/Intranet/ITCF/Shared%20Documents/Forms/AllItems.aspx?id=%2Fsites%2FGTS%2DICC%2FIntranet%2FITCF%2FShared%20Documents%2FEnablers%20%26%20Checklists&viewid=99189f90%2Df2b0%2D478b%2Da980%2Df93a529e9b18","ITCF - Protect - P04.01.02 Information Security Classification Schema - Appendix A (2021)") | L4: =HYPERLINK("https://aegonna.sharepoint.com/sites/GTS-ICC/Intranet/ITCF/Shared%20Documents/Forms/AllItems.aspx?id=%2Fsites%2FGTS%2DICC%2FIntranet%2FITCF%2FShared%20Documents%2FEnablers%20%26%20Checklists&viewid=99189f90%2Df2b0%2D478b%2Da980%2Df93a529e9b18","ITCF - Protect - P04.01.02 Information Security Classification Schema - Appendix A (2021)") -> ITCF - Protect - P04.01.02 Information Security Classification Schema - Appendix A (2021)
A5: Data Privacy | C5: Is the solution aligned with our Data Management Policy? | D5: Yes | E5: =VLOOKUP(D5,References!H:I,2,FALSE) -> 1 | H5: =HYPERLINK("https://aegon.sharepoint.com/sites/CC-PolicyHouseGroup-10099/Shared%20Documents/Data%20Management%20Policy.pdf","Data Management Policy (2025)") -> Data Management Policy (2025) | J5: https://aegon.sharepoint.com/sites/CC-PolicyHouseGroup-10099/Shared%20Documents/Data%20Management%20Policy.pdf | K5: =CONCATENATE("=hyperlink(""",J5,""",""",H5,""")") -> =hyperlink("https://aegon.sharepoint.com/sites/CC-PolicyHouseGroup-10099/Shared%20Documents/Data%20Management%20Policy.pdf","Data Management Policy (2025)") | L5: =HYPERLINK("https://aegon.sharepoint.com/sites/CC-PolicyHouseGroup-10099/Shared%20Documents/Data%20Management%20Policy.pdf","Data Management Policy (2025)") -> Data Management Policy (2025)
A6: Data Protection | C6: Is the solution aligned with our Data Encryption Standards? | D6: Yes | E6: =VLOOKUP(D6,References!H:I,2,FALSE) -> 1 | H6: =HYPERLINK("https://aegonna.sharepoint.com/:b:/r/sites/TA-TAInformationSecurityPoliciesandStandards/Public/Transamerica%20Encryption%20Standards.pdf?csf=1&web=1&e=ehl5EJ","Transamerica Encryption Standards (2025)") -> Transamerica Encryption Standards (2025) | J6: https://aegonna.sharepoint.com/:b:/r/sites/TA-TAInformationSecurityPoliciesandStandards/Public/Transamerica%20Encryption%20Standards.pdf?csf=1&web=1&e=ehl5EJ | K6: =CONCATENATE("=hyperlink(""",J6,""",""",H6,""")") -> =hyperlink("https://aegonna.sharepoint.com/:b:/r/sites/TA-TAInformationSecurityPoliciesandStandards/Public/Transamerica%20Encryption%20Standards.pdf?csf=1&web=1&e=ehl5EJ","Transamerica Encryption Standards (2025)") | L6: =HYPERLINK("https://aegonna.sharepoint.com/:b:/r/sites/TA-TAInformationSecurityPoliciesandStandards/Public/Transamerica%20Encryption%20Standards.pdf?csf=1&web=1&e=ehl5EJ","Transamerica Encryption Standards (2025)") -> Transamerica Encryption Standards (2025)
A7: Data Privacy | C7: Is the use of production data limited to production environments? | D7: Yes | E7: =VLOOKUP(D7,References!H:I,2,FALSE) -> 1 | K7: =CONCATENATE("=hyperlink(""",J7,""",""",H7,""")") -> =hyperlink("","") | L7: =HYPERLINK("","")
A8: Data Privacy | C8: If this is a Solution Design Final and the solution leverages new data sources or new use cases for data, has a Data Protection / Privacy Impact Assessment (DPIA) been completed? | D8: Assessment Not Required | E8: =VLOOKUP(D8,References!S:T,2,FALSE) -> 1 | G8: For Component Standards, complete the OneTrust Asset Discovery Questionaire | H8: =HYPERLINK("https://app-de.onetrust.com/auth/login","OneTrust Application") -> OneTrust Application | I8: =HYPERLINK("https://aegonna.sharepoint.com/:p:/r/sites/GEA/Templates/In%20Review/2026%20Enterprise%20Technology%20ARB%20Charter%20%26%20Architecture%20Processes%20Overview.pptx?d=w751dcb168e6d4cc5bd0a17ac94837e7c&csf=1&web=1&e=ZMbkEw","Enterprise Technology ARB Charter - Data Privacy & Protection / Non-Private Data Usage (2026)") -> Enterprise Technology ARB Charter - Data Privacy & Protection / Non-Private Data Usage (2026) | J8: https://app-de.onetrust.com/auth/login | K8: =CONCATENATE("=hyperlink(""",J8,""",""",H8,""")") -> =hyperlink("https://app-de.onetrust.com/auth/login","OneTrust Application") | L8: =HYPERLINK("https://app-de.onetrust.com/auth/login","OneTrust Application") -> OneTrust Application
J9: https://aegonna.sharepoint.com/:p:/r/sites/GEA/Templates/In%20Review/2026%20Enterprise%20Technology%20ARB%20Charter%20%26%20Architecture%20Processes%20Overview.pptx?d=w751dcb168e6d4cc5bd0a17ac94837e7c&csf=1&web=1&e=ZMbkEw | K9: =CONCATENATE("=hyperlink(""",J9,""",""",I8,""")") -> =hyperlink("https://aegonna.sharepoint.com/:p:/r/sites/GEA/Templates/In%20Review/2026%20Enterprise%20Technology%20ARB%20Charter%20%26%20Architecture%20Processes%20Overview.pptx?d=w751dcb168e6d4cc5bd0a17ac94837e7c&csf=1&web=1&e=ZMbkEw","Enterprise Technology ARB Charter - Data Privacy & Protection / Non-Private Data Usage (2026)") | L9: =HYPERLINK("https://aegonna.sharepoint.com/:p:/r/sites/GEA/Templates/In%20Review/2026%20Enterprise%20Technology%20ARB%20Charter%20%26%20Architecture%20Processes%20Overview.pptx?d=w751dcb168e6d4cc5bd0a17ac94837e7c&csf=1&web=1&e=ZMbkEw","Enterprise Technology ARB Charter - Data Privacy & Protection / Non-Private Data Usage (2026)") -> Enterprise Technology ARB Charter - Data Privacy & Protection / Non-Private Data Usage (2026)

Sheet Gen AI
A1: GEN AI DOMAIN | E1: =SUM(E3:E6)/COUNT(E3:E6) -> 1
A2: Category | B2: Review Group | C2: Question | D2: Answer | E2: Scoring | F2: Comments to Explain Answer (Complete this column if explanation is necessary) | G2: Instructions | H2: Links and Further Instructions | L2: Links and Further Instructions
A3: Gen AI | C3: Are GEN AI use cases a part of the solution design? | D3: N/A | E3: 1 | H3: =HYPERLINK("https://aegon.sharepoint.com/:b:/r/sites/CC-PolicyHouseGroup-10099/Shared%20Documents/Generative%20AI%20Policy.pdf?csf=1&web=1&e=ER9yPo","Global Gen AI Policy (2025)") -> Global Gen AI Policy (2025) | I3: https://aegon.sharepoint.com/:b:/r/sites/CC-PolicyHouseGroup-10099/Shared%20Documents/Generative%20AI%20Policy.pdf?csf=1&web=1&e=ER9yPo | J3: =CONCATENATE("=hyperlink(""",I3,""",""",H3,""")") -> =hyperlink("https://aegon.sharepoint.com/:b:/r/sites/CC-PolicyHouseGroup-10099/Shared%20Documents/Generative%20AI%20Policy.pdf?csf=1&web=1&e=ER9yPo","Global Gen AI Policy (2025)") | K3: =HYPERLINK("https://aegon.sharepoint.com/:b:/r/sites/CC-PolicyHouseGroup-10099/Shared%20Documents/Generative%20AI%20Policy.pdf?csf=1&web=1&e=ER9yPo","Global Gen AI Policy (2025)") -> Global Gen AI Policy (2025)
A4: Gen AI | C4: Is the GEN AI Inventory updated with the use cases and is it Approved? | D4: No GEN AI | E4: =VLOOKUP(D4,References!AE:AF,2,FALSE) -> 1 | G4: Input GEN AI Inventory Number | H4: =HYPERLINK("https://aegon.sharepoint.com/sites/GTS-GlobalAIInventory-GTS-GenAI/Lists/Global%20AI%20Inventory%20%20GTS/AllItems.aspx","GenAI Inventory (SharePoint Site)") -> GenAI Inventory (SharePoint Site) | I4: https://aegon.sharepoint.com/sites/GTS-GlobalAIInventory-GTS-GenAI/Lists/Global%20AI%20Inventory%20%20GTS/AllItems.aspx | J4: =CONCATENATE("=hyperlink(""",I4,""",""",H4,""")") -> =hyperlink("https://aegon.sharepoint.com/sites/GTS-GlobalAIInventory-GTS-GenAI/Lists/Global%20AI%20Inventory%20%20GTS/AllItems.aspx","GenAI Inventory (SharePoint Site)") | K4: =HYPERLINK("https://aegon.sharepoint.com/sites/GTS-GlobalAIInventory-GTS-GenAI/Lists/Global%20AI%20Inventory%20%20GTS/AllItems.aspx","GenAI Inventory (SharePoint Site)") -> GenAI Inventory (SharePoint Site)
A5: Gen AI | C5: Is the GEN AI Risk Rating is assigned? | D5: No GEN AI | E5: =VLOOKUP(D5,References!AE:AF,2,FALSE) -> 1 | G5: Input Gen AI Risk Rating | H5: =HYPERLINK("https://aegon.sharepoint.com/sites/GTS-GlobalAIInventory-GTS-GenAI/Lists/Global%20AI%20Inventory%20%20GTS/AllItems.aspx","GenAI Inventory (SharePoint Site)") -> GenAI Inventory (SharePoint Site) | I5: https://aegon.sharepoint.com/sites/GTS-GlobalAIInventory-GTS-GenAI/Lists/Global%20AI%20Inventory%20%20GTS/AllItems.aspx | J5: =CONCATENATE("=hyperlink(""",I5,""",""",H5,""")") -> =hyperlink("https://aegon.sharepoint.com/sites/GTS-GlobalAIInventory-GTS-GenAI/Lists/Global%20AI%20Inventory%20%20GTS/AllItems.aspx","GenAI Inventory (SharePoint Site)") | K5: =HYPERLINK("https://aegon.sharepoint.com/sites/GTS-GlobalAIInventory-GTS-GenAI/Lists/Global%20AI%20Inventory%20%20GTS/AllItems.aspx","GenAI Inventory (SharePoint Site)") -> GenAI Inventory (SharePoint Site) | L5: Holly Roth is the contact for the GEN AI group. The distribution email is: AITeam@transamerica.com
A6: Gen AI | C6: For new LLMs, what is the LLM Impact Assessment Status? | D6: Assessment Not Required | E6: =VLOOKUP(D6,References!S:T,2,FALSE) -> 1 | G6: Required to be Completed for FINALs where first time use of LLM is in Scope | H6: =HYPERLINK("https://aegonna.sharepoint.com/sites/GTS-GlobalEngineeringandArchitecture/Shared%20Documents/GTS%20Architecture%20Documents/Intake%20Process/GenAI%20Documentation/LLM%20IMPACT%20ASSESSMENT.docx","LLM Impact Assessment Form (Word Doc)") -> LLM Impact Assessment Form (Word Doc) | I6: https://aegonna.sharepoint.com/GTS-GlobalEngineeringandArchitecture/Shared%20Documents/GTS%20Architecture%20Documents/Intake%20Process/GenAI%20Documentation/LLM%20IMPACT%20ASSESSMENT.docx | J6: =CONCATENATE("=hyperlink(""",I6,""",""",H6,""")") -> =hyperlink("https://aegonna.sharepoint.com/GTS-GlobalEngineeringandArchitecture/Shared%20Documents/GTS%20Architecture%20Documents/Intake%20Process/GenAI%20Documentation/LLM%20IMPACT%20ASSESSMENT.docx","LLM Impact Assessment Form (Word Doc)") | K6: =HYPERLINK("https://aegonna.sharepoint.com/GTS-GlobalEngineeringandArchitecture/Shared%20Documents/GTS%20Architecture%20Documents/Intake%20Process/GenAI%20Documentation/LLM%20IMPACT%20ASSESSMENT.docx","LLM Impact Assessment Form (Word Doc)") -> LLM Impact Assessment Form (Word Doc)

Sheet Security
A1: SECURITY DOMAIN | D1: =SUM(D3:D13)/COUNT(D3:D13) -> 0.81818182
A2: Category | B2: Question | C2: Answer | D2: Scoring | E2: Comments to Explain Answer (Complete this column if explanation is necessary) | F2: Instructions | G2: Links and Further Instructions
A3: Security | B3: Is the solution aligned with our Network/Application Segmentation Guidance? | C3: Yes | D3: =VLOOKUP(C3,References!D:E,2,FALSE) -> 1 | G3: =HYPERLINK("https://aegonna.sharepoint.com/:w:/r/sites/GTS-GlobalARB/Shared%20Documents/Global%20Cloud%20Application%20Network%20Segmentation%20Guidance/Global%20Cloud%20Application%20Network%20Segmentation%20Guidance.docx","Global Cloud Application Network Segmentation Guidance (Draft - 2026)") -> Global Cloud Application Network Segmentation Guidance (Draft - 2026) | H3: https://aegonna.sharepoint.com/:w:/r/sites/GTS-GlobalARB/Shared%20Documents/Global%20Cloud%20Application%20Network%20Segmentation%20Guidance/Global%20Cloud%20Application%20Network%20Segmentation%20Guidance.docx | I3: =CONCATENATE("=hyperlink(""",H3,""",""",G3,""")") -> =hyperlink("https://aegonna.sharepoint.com/:w:/r/sites/GTS-GlobalARB/Shared%20Documents/Global%20Cloud%20Application%20Network%20Segmentation%20Guidance/Global%20Cloud%20Application%20Network%20Segmentation%20Guidance.docx","Global Cloud Application Network Segmentation Guidance (Draft - 2026)") | J3: =HYPERLINK("https://aegonna.sharepoint.com/:w:/r/sites/GTS-GlobalARB/Shared%20Documents/Global%20Cloud%20Application%20Network%20Segmentation%20Guidance/Global%20Cloud%20Application%20Network%20Segmentation%20Guidance.docx","Global Cloud Application Network Segmentation Guidance (Draft - 2026)") -> Global Cloud Application Network Segmentation Guidance (Draft - 2026)
A4: Security | B4: Is the solution aligned with the Transamerica Security Logging & Monitoring Process? | C4: N/A | D4: =VLOOKUP(C4,References!D:E,2,FALSE) -> 1 | G4: =HYPERLINK("https://aegonna.sharepoint.com/:b:/r/sites/TA-TAInformationSecurityPoliciesandStandards/Public/Transamerica%20Logging%20and%20Monitoring%20Process.pdf?csf=1&web=1&e=tXZpbL","Transamerica Security Logging & Monitoring Process (2025)") -> Transamerica Security Logging & Monitoring Process (2025) | H4: https://aegonna.sharepoint.com/:b:/r/sites/TA-TAInformationSecurityPoliciesandStandards/Public/Transamerica%20Logging%20and%20Monitoring%20Process.pdf?csf=1&web=1&e=tXZpbL | I4: =CONCATENATE("=hyperlink(""",H4,""",""",G4,""")") -> =hyperlink("https://aegonna.sharepoint.com/:b:/r/sites/TA-TAInformationSecurityPoliciesandStandards/Public/Transamerica%20Logging%20and%20Monitoring%20Process.pdf?csf=1&web=1&e=tXZpbL","Transamerica Security Logging & Monitoring Process (2025)") | J4: =HYPERLINK("https://aegonna.sharepoint.com/:b:/r/sites/TA-TAInformationSecurityPoliciesandStandards/Public/Transamerica%20Logging%20and%20Monitoring%20Process.pdf?csf=1&web=1&e=tXZpbL","Transamerica Security Logging & Monitoring Process (2025)") -> Transamerica Security Logging & Monitoring Process (2025)
A5: Security | B5: Does the architecture integrate with approved Identity and Access Management tooling? | C5: Yes | D5: =VLOOKUP(C5,References!D:E,2,FALSE) -> 1 | F5: PingOne, Okta, ISAM | G5: =HYPERLINK("https://aegonna.sharepoint.com/:w:/r/sites/GTS-GlobalARB/Global%20Architecture%20Informational%20Presentations/GTS%20Architecture%20CIAM%20Position%20Paper.docx?d=w82978e8df5654367b76bc39f9a585957&csf=1&web=1&e=lGjf0q","Global Architecture IAM Position Paper (2024)") -> Global Architecture IAM Position Paper (2024) | H5: https://aegonna.sharepoint.com/:w:/r/sites/GTS-GlobalARB/Global%20Architecture%20Informational%20Presentations/GTS%20Architecture%20CIAM%20Position%20Paper.docx?d=w82978e8df5654367b76bc39f9a585957&csf=1&web=1&e=lGjf0q | I5: =CONCATENATE("=hyperlink(""",H5,""",""",G5,""")") -> =hyperlink("https://aegonna.sharepoint.com/:w:/r/sites/GTS-GlobalARB/Global%20Architecture%20Informational%20Presentations/GTS%20Architecture%20CIAM%20Position%20Paper.docx?d=w82978e8df5654367b76bc39f9a585957&csf=1&web=1&e=lGjf0q","Global Architecture IAM Position Paper (2024)") | J5: =HYPERLINK("https://aegonna.sharepoint.com/:w:/r/sites/GTS-GlobalARB/Global%20Architecture%20Informational%20Presentations/GTS%20Architecture%20CIAM%20Position%20Paper.docx?d=w82978e8df5654367b76bc39f9a585957&csf=1&web=1&e=lGjf0q","Global Architecture IAM Position Paper (2024)") -> Global Architecture IAM Position Paper (2024)
A6: Security | B6: Is the solution integrated with our Identity Access Governance platform tool and processes | C6: Yes | D6: =VLOOKUP(C6,References!D:E,2,FALSE) -> 1 | F6: Sailpoint | G6: =HYPERLINK("https://aegonna.sharepoint.com/:w:/r/sites/GEA/Project%20Solutions/SailPoint%20Solution%20Design%20Updates.docx?d=w474be95ffaae41a78a1451567eaa0d91&csf=1&web=1&e=Ryfqym","SailPoint Solution Design (2025)") -> SailPoint Solution Design (2025) | H6: https://aegonna.sharepoint.com/:w:/r/sites/GEA/Project%20Solutions/SailPoint%20Solution%20Design%20Updates.docx?d=w474be95ffaae41a78a1451567eaa0d91&csf=1&web=1&e=Ryfqym | I6: =CONCATENATE("=hyperlink(""",H6,""",""",G6,""")") -> =hyperlink("https://aegonna.sharepoint.com/:w:/r/sites/GEA/Project%20Solutions/SailPoint%20Solution%20Design%20Updates.docx?d=w474be95ffaae41a78a1451567eaa0d91&csf=1&web=1&e=Ryfqym","SailPoint Solution Design (2025)") | J6: =HYPERLINK("https://aegonna.sharepoint.com/:w:/r/sites/GEA/Project%20Solutions/SailPoint%20Solution%20Design%20Updates.docx?d=w474be95ffaae41a78a1451567eaa0d91&csf=1&web=1&e=Ryfqym","SailPoint Solution Design (2025)") -> SailPoint Solution Design (2025)
